Workbook

Sheet README
A1: DESK BACKTEST — METHODOLOGY & WORKBOOK GUIDE
A3: Purpose
A4: Quantify The Desk's calibration and edge against historical World Cup, Euro, and Copa America data. The deliverable is a calibration story we can defend — not a hit-rate brag.
A6: What gets measured
A7: • Brier score per match per time-window (lower = better calibrated). Compared against the closing market as the baseline-to-beat.
A8: • Reliability diagram: bin all (probability, outcome) pairs and check whether predicted rates match observed rates within each bin.
A9: • Pick-vs-market head-to-head: when The Desk Picked and the market disagreed, who was right?
A10: • Hit rate of Picks — sanity check only, never the headline number.
A12: Time windows per match
A13: Each match is snapshotted at four points to show how calibration evolves as kickoff approaches:
A14: T−38d · pre-tournament (fundamentals only — Elo, host venue, altitude)
A15: T−5d · weather forecast added
... A39: Scaffold delivered with five WC 2022 matches as ILLUSTRATIVE EXAMPLES (clearly marked). Real Elo / closing-market / news-feed data ingestion required before metrics can be trusted.

Sheet Match Universe
A1: match_id | B1: tournament | C1: stage | D1: kickoff_utc | E1: team_a | F1: team_b | G1: venue_city | H1: venue_country | I1: result_a | J1: result_b | K1: winner | L1: is_example
A2: wc22-a-qat-ecu-20221120 | B2: FIFA World Cup 2022 | C2: Group A | D2: 2022-11-20 16:00 | E2: Qatar | F2: Ecuador | G2: Al Khor | H2: QA | I2: 0 | J2: 2 | K2: b | L2: BACKTEST wc 2022
A3: wc22-b-eng-irn-20221121 | B3: FIFA World Cup 2022 | C3: Group B | D3: 2022-11-21 13:00 | E3: England | F3: Iran | G3: Doha | H3: QA | I3: 6 | J3: 2 | K3: a | L3: BACKTEST wc 2022
A4: wc22-a-sen-ned-20221121 | B4: FIFA World Cup 2022 | C4: Group A | D4: 2022-11-21 16:00 | E4: Senegal | F4: Netherlands | G4: Doha | H4: QA | I4: 0 | J4: 2 | K4: b | L4: BACKTEST wc 2022
A5: wc22-b-usa-wal-20221121 | B5: FIFA World Cup 2022 | C5: Group B | D5: 2022-11-21 19:00 | E5: USA | F5: Wales | G5: Al Rayyan | H5: QA | I5: 1 | J5: 1 | K5: draw | L5: BACKTEST wc 2022
A6: wc22-c-arg-sau-20221122 | B6: FIFA World Cup 2022 | C6: Group C | D6: 2022-11-22 10:00 | E6: Argentina | F6: Saudi Arabia | G6: Lusail | H6: QA | I6: 1 | J6: 2 | K6: b | L6: BACKTEST wc 2022
A7: wc22-d-den-tun-20221122 | B7: FIFA World Cup 2022 | C7: Group D | D7: 2022-11-22 13:00 | E7: Denmark | F7: Tunisia | G7: Al Rayyan | H7: QA | I7: 0 | J7: 0 | K7: draw | L7: BACKTEST wc 2022
A8: wc22-c-mex-pol-20221122 | B8: FIFA World Cup 2022 | C8: Group C | D8: 2022-11-22 16:00 | E8: Mexico | F8: Poland | G8: Doha | H8: QA | I8: 0 | J8: 0 | K8: draw | L8: BACKTEST wc 2022
A9: wc22-d-fra-aus-20221122 | B9: FIFA World Cup 2022 | C9: Group D | D9: 2022-11-22 19:00 | E9: France | F9: Australia | G9: Al Wakrah | H9: QA | I9: 4 | J9: 1 | K9: a | L9: BACKTEST wc 2022
A10: wc22-f-mar-cro-20221123 | B10: FIFA World Cup 2022 | C10: Group F | D10: 2022-11-23 10:00 | E10: Morocco | F10: Croatia | G10: Al Khor | H10: QA | I10: 0 | J10: 0 | K10: draw | L10: BACKTEST wc 2022
A11: wc22-e-ger-jpn-20221123 | B11: FIFA World Cup 2022 | C11: Group E | D11: 2022-11-23 13:00 | E11: Germany | F11: Japan | G11: Doha | H11: QA | I11: 1 | J11: 2 | K11: b | L11: BACKTEST wc 2022
A12: wc22-e-esp-crc-20221123 | B12: FIFA World Cup 2022 | C12: Group E | D12: 2022-11-23 16:00 | E12: Spain | F12: Costa Rica | G12: Doha | H12: QA | I12: 7 | J12: 0 | K12: a | L12: BACKTEST wc 2022
A13: wc22-f-bel-can-20221123 | B13: FIFA World Cup 2022 | C13: Group F | D13: 2022-11-23 19:00 | E13: Belgium | F13: Canada | G13: Al Rayyan | H13: QA | I13: 1 | J13: 0 | K13: a | L13: BACKTEST wc 2022
... A65: wc22-fin-arg-fra-20221218 | B65: FIFA World Cup 2022 | C65: Final | D65: 2022-12-18 15:00 | E65: Argentina | F65: France | G65: Lusail | H65: QA | I65: 3 | J65: 3 | K65: draw | L65: BACKTEST wc 2022

Sheet Snapshots
A1: match_id | B1: window | C1: elo_a | D1: elo_b | E1: host_bonus | F1: altitude_m | G1: weather_factor | H1: injury_factor | I1: p_a | J1: p_draw | K1: p_b | L1: market_p_a | M1: market_p_draw | N1: market_p_b | O1: actual_a | P1: actual_draw | Q1: actual_b | R1: verdict_state | S1: verdict_side | T1: verdict_market_venue | U1: verdict_edge_pp | V1: brier_score | W1: verdict_resolved | X1: is_example
A2: wc22-a-qat-ecu-20221120 | B2: T-38 | C2: 1680 | D2: 1820 | E2: 75 | F2: 12 | G2: 1 | H2: 1 | I2: 0.301167 | J2: 0.261 | K2: 0.437833 | L2: 0.279718 | M2: 0.306787 | N2: 0.413495 | O2: 0 | P2: 0 | Q2: 0 | R2: pass | V2: =(I2-O2)^2+(J2-P2)^2+(K2-Q2)^2 | W2: =IF(B2<>"KO","",IF(R2="pick",IF(VLOOKUP(A2,'Match Universe'!A:K,11,FALSE)=S2,"hit","miss"),IF(R2="pass","n/a","n/a"))) | X2: BACKTEST wc 2022
A3: wc22-a-qat-ecu-20221120 | B3: T-5 | C3: 1680 | D3: 1820 | E3: 75 | F3: 12 | G3: 1 | H3: 1 | I3: 0.301167 | J3: 0.261 | K3: 0.437833 | L3: 0.279718 | M3: 0.306787 | N3: 0.413495 | O3: 0 | P3: 0 | Q3: 0 | R3: pass | V3: =(I3-O3)^2+(J3-P3)^2+(K3-Q3)^2 | W3: =IF(B3<>"KO","",IF(R3="pick",IF(VLOOKUP(A3,'Match Universe'!A:K,11,FALSE)=S3,"hit","miss"),IF(R3="pass","n/a","n/a"))) | X3: BACKTEST wc 2022
A4: wc22-a-qat-ecu-20221120 | B4: T-1h | C4: 1680 | D4: 1820 | E4: 75 | F4: 12 | G4: 1 | H4: 1 | I4: 0.301167 | J4: 0.261 | K4: 0.437833 | L4: 0.279718 | M4: 0.306787 | N4: 0.413495 | O4: 0 | P4: 0 | Q4: 0 | R4: pass | V4: =(I4-O4)^2+(J4-P4)^2+(K4-Q4)^2 | W4: =IF(B4<>"KO","",IF(R4="pick",IF(VLOOKUP(A4,'Match Universe'!A:K,11,FALSE)=S4,"hit","miss"),IF(R4="pass","n/a","n/a"))) | X4: BACKTEST wc 2022
A5: wc22-a-qat-ecu-20221120 | B5: KO | C5: 1680 | D5: 1820 | E5: 75 | F5: 12 | G5: 1 | H5: 1 | I5: 0.301167 | J5: 0.261 | K5: 0.437833 | L5: 0.279718 | M5: 0.306787 | N5: 0.413495 | O5: 0 | P5: 0 | Q5: 1 | R5: pass | V5: =(I5-O5)^2+(J5-P5)^2+(K5-Q5)^2 | W5: =IF(B5<>"KO","",IF(R5="pick",IF(VLOOKUP(A5,'Match Universe'!A:K,11,FALSE)=S5,"hit","miss"),IF(R5="pass","n/a","n/a"))) | X5: BACKTEST wc 2022
A6: wc22-b-eng-irn-20221121 | B6: T-38 | C6: 2020 | D6: 1818 | E6: 0 | F6: 8 | G6: 1 | H6: 1 | I6: 0.625625 | J6: 0.1788 | K6: 0.195575 | L6: 0.700943 | M6: 0.196553 | N6: 0.102504 | O6: 0 | P6: 0 | Q6: 0 | R6: pass | V6: =(I6-O6)^2+(J6-P6)^2+(K6-Q6)^2 | W6: =IF(B6<>"KO","",IF(R6="pick",IF(VLOOKUP(A6,'Match Universe'!A:K,11,FALSE)=S6,"hit","miss"),IF(R6="pass","n/a","n/a"))) | X6: BACKTEST wc 2022
A7: wc22-b-eng-irn-20221121 | B7: T-5 | C7: 2020 | D7: 1818 | E7: 0 | F7: 8 | G7: 1 | H7: 1 | I7: 0.625625 | J7: 0.1788 | K7: 0.195575 | L7: 0.700943 | M7: 0.196553 | N7: 0.102504 | O7: 0 | P7: 0 | Q7: 0 | R7: pass | V7: =(I7-O7)^2+(J7-P7)^2+(K7-Q7)^2 | W7: =IF(B7<>"KO","",IF(R7="pick",IF(VLOOKUP(A7,'Match Universe'!A:K,11,FALSE)=S7,"hit","miss"),IF(R7="pass","n/a","n/a"))) | X7: BACKTEST wc 2022
A8: wc22-b-eng-irn-20221121 | B8: T-1h | C8: 2020 | D8: 1818 | E8: 0 | F8: 8 | G8: 1 | H8: 1 | I8: 0.625625 | J8: 0.1788 | K8: 0.195575 | L8: 0.700943 | M8: 0.196553 | N8: 0.102504 | O8: 0 | P8: 0 | Q8: 0 | R8: pass | V8: =(I8-O8)^2+(J8-P8)^2+(K8-Q8)^2 | W8: =IF(B8<>"KO","",IF(R8="pick",IF(VLOOKUP(A8,'Match Universe'!A:K,11,FALSE)=S8,"hit","miss"),IF(R8="pass","n/a","n/a"))) | X8: BACKTEST wc 2022
A9: wc22-b-eng-irn-20221121 | B9: KO | C9: 2020 | D9: 1818 | E9: 0 | F9: 8 | G9: 1 | H9: 1 | I9: 0.625625 | J9: 0.1788 | K9: 0.195575 | L9: 0.700943 | M9: 0.196553 | N9: 0.102504 | O9: 1 | P9: 0 | Q9: 0 | R9: pass | V9: =(I9-O9)^2+(J9-P9)^2+(K9-Q9)^2 | W9: =IF(B9<>"KO","",IF(R9="pick",IF(VLOOKUP(A9,'Match Universe'!A:K,11,FALSE)=S9,"hit","miss"),IF(R9="pass","n/a","n/a"))) | X9: BACKTEST wc 2022
A10: wc22-a-sen-ned-20221121 | B10: T-38 | C10: 1858 | D10: 2040 | E10: 0 | F10: 2 | G10: 1 | H10: 1 | I10: 0.210126 | J10: 0.1908 | K10: 0.599074 | L10: 0.271396 | M10: 0.296839 | N10: 0.431766 | O10: 0 | P10: 0 | Q10: 0 | R10: pass | V10: =(I10-O10)^2+(J10-P10)^2+(K10-Q10)^2 | W10: =IF(B10<>"KO","",IF(R10="pick",IF(VLOOKUP(A10,'Match Universe'!A:K,11,FALSE)=S10,"hit","miss"),IF(R10="pass","n/a","n/a"))) | X10: BACKTEST wc 2022
A11: wc22-a-sen-ned-20221121 | B11: T-5 | C11: 1858 | D11: 2040 | E11: 0 | F11: 2 | G11: 1 | H11: 1 | I11: 0.210126 | J11: 0.1908 | K11: 0.599074 | L11: 0.271396 | M11: 0.296839 | N11: 0.431766 | O11: 0 | P11: 0 | Q11: 0 | R11: pass | V11: =(I11-O11)^2+(J11-P11)^2+(K11-Q11)^2 | W11: =IF(B11<>"KO","",IF(R11="pick",IF(VLOOKUP(A11,'Match Universe'!A:K,11,FALSE)=S11,"hit","miss"),IF(R11="pass","n/a","n/a"))) | X11: BACKTEST wc 2022
A12: wc22-a-sen-ned-20221121 | B12: T-1h | C12: 1858 | D12: 2040 | E12: 0 | F12: 2 | G12: 1 | H12: 1 | I12: 0.210126 | J12: 0.1908 | K12: 0.599074 | L12: 0.271396 | M12: 0.296839 | N12: 0.431766 | O12: 0 | P12: 0 | Q12: 0 | R12: pass | V12: =(I12-O12)^2+(J12-P12)^2+(K12-Q12)^2 | W12: =IF(B12<>"KO","",IF(R12="pick",IF(VLOOKUP(A12,'Match Universe'!A:K,11,FALSE)=S12,"hit","miss"),IF(R12="pass","n/a","n/a"))) | X12: BACKTEST wc 2022
A13: wc22-a-sen-ned-20221121 | B13: KO | C13: 1858 | D13: 2040 | E13: 0 | F13: 2 | G13: 1 | H13: 1 | I13: 0.210126 | J13: 0.1908 | K13: 0.599074 | L13: 0.271396 | M13: 0.296839 | N13: 0.431766 | O13: 0 | P13: 0 | Q13: 1 | R13: pass | V13: =(I13-O13)^2+(J13-P13)^2+(K13-Q13)^2 | W13: =IF(B13<>"KO","",IF(R13="pick",IF(VLOOKUP(A13,'Match Universe'!A:K,11,FALSE)=S13,"hit","miss"),IF(R13="pass","n/a","n/a"))) | X13: BACKTEST wc 2022
... A37: wc22-f-mar-cro-20221123 | B37: KO | C37: 1779 | D37: 1920 | E37: 0 | F37: 12 | G37: 1 | H37: 1 | I37: 0.241293 | J37: 0.2154 | K37: 0.543307 | L37: 0.171075 | M37: 0.298002 | N37: 0.530923 | O37: 0 | P37: 1 | Q37: 0 | R37: pass | V37: =(I37-O37)^2+(J37-P37)^2+(K37-Q37)^2 | W37: =IF(B37<>"KO","",IF(R37="pick",IF(VLOOKUP(A37,'Match Universe'!A:K,11,FALSE)=S37,"hit","miss"),IF(R37="pass","n/a","n/a"))) | X37: BACKTEST wc 2022
A38: wc22-e-ger-jpn-20221123 | B38: T-38 | C38: 1968 | D38: 1812 | E38: 0 | F38: 8 | G38: 1 | H38: 1 | I38: 0.563885 | J38: 0.2064 | K38: 0.229715 | L38: 0.662935 | M38: 0.210666 | N38: 0.1264 | O38: 0 | P38: 0 | Q38: 0 | R38: pick | S38: Japan | T38: polymarket | U38: 10.33 | V38: =(I38-O38)^2+(J38-P38)^2+(K38-Q38)^2 | W38: =IF(B38<>"KO","",IF(R38="pick",IF(VLOOKUP(A38,'Match Universe'!A:K,11,FALSE)=S38,"hit","miss"),IF(R38="pass","n/a","n/a"))) | X38: BACKTEST wc 2022
A39: wc22-e-ger-jpn-20221123 | B39: T-5 | C39: 1968 | D39: 1812 | E39: 0 | F39: 8 | G39: 1 | H39: 1 | I39: 0.563885 | J39: 0.2064 | K39: 0.229715 | L39: 0.662935 | M39: 0.210666 | N39: 0.1264 | O39: 0 | P39: 0 | Q39: 0 | R39: pick | S39: Japan | T39: polymarket | U39: 10.33 | V39: =(I39-O39)^2+(J39-P39)^2+(K39-Q39)^2 | W39: =IF(B39<>"KO","",IF(R39="pick",IF(VLOOKUP(A39,'Match Universe'!A:K,11,FALSE)=S39,"hit","miss"),IF(R39="pass","n/a","n/a"))) | X39: BACKTEST wc 2022
A40: wc22-e-ger-jpn-20221123 | B40: T-1h | C40: 1968 | D40: 1812 | E40: 0 | F40: 8 | G40: 1 | H40: 1 | I40: 0.563885 | J40: 0.2064 | K40: 0.229715 | L40: 0.662935 | M40: 0.210666 | N40: 0.1264 | O40: 0 | P40: 0 | Q40: 0 | R40: pick | S40: Japan | T40: polymarket | U40: 10.33 | V40: =(I40-O40)^2+(J40-P40)^2+(K40-Q40)^2 | W40: =IF(B40<>"KO","",IF(R40="pick",IF(VLOOKUP(A40,'Match Universe'!A:K,11,FALSE)=S40,"hit","miss"),IF(R40="pass","n/a","n/a"))) | X40: BACKTEST wc 2022
A41: wc22-e-ger-jpn-20221123 | B41: KO | C41: 1968 | D41: 1812 | E41: 0 | F41: 8 | G41: 1 | H41: 1 | I41: 0.563885 | J41: 0.2064 | K41: 0.229715 | L41: 0.662935 | M41: 0.210666 | N41: 0.1264 | O41: 0 | P41: 0 | Q41: 1 | R41: pick | S41: Japan | T41: polymarket | U41: 10.33 | V41: =(I41-O41)^2+(J41-P41)^2+(K41-Q41)^2 | W41: =IF(B41<>"KO","",IF(R41="pick",IF(VLOOKUP(A41,'Match Universe'!A:K,11,FALSE)=S41,"hit","miss"),IF(R41="pass","n/a","n/a"))) | X41: BACKTEST wc 2022
A42: wc22-e-esp-crc-20221123 | B42: T-38 | C42: 2048 | D42: 1741 | E42: 0 | F42: 8 | G42: 1 | H42: 1 | I42: 0.755207 | J42: 0.1158 | K42: 0.128993 | L42: 0.852692 | M42: 0.101425 | N42: 0.045883 | O42: 0 | P42: 0 | Q42: 0 | R42: pick | S42: Costa Rica | T42: polymarket | U42: 8.31 | V42: =(I42-O42)^2+(J42-P42)^2+(K42-Q42)^2 | W42: =IF(B42<>"KO","",IF(R42="pick",IF(VLOOKUP(A42,'Match Universe'!A:K,11,FALSE)=S42,"hit","miss"),IF(R42="pass","n/a","n/a"))) | X42: BACKTEST wc 2022
A43: wc22-e-esp-crc-20221123 | B43: T-5 | C43: 2048 | D43: 1741 | E43: 0 | F43: 8 | G43: 1 | H43: 1 | I43: 0.755207 | J43: 0.1158 | K43: 0.128993 | L43: 0.852692 | M43: 0.101425 | N43: 0.045883 | O43: 0 | P43: 0 | Q43: 0 | R43: pick | S43: Costa Rica | T43: polymarket | U43: 8.31 | V43: =(I43-O43)^2+(J43-P43)^2+(K43-Q43)^2 | W43: =IF(B43<>"KO","",IF(R43="pick",IF(VLOOKUP(A43,'Match Universe'!A:K,11,FALSE)=S43,"hit","miss"),IF(R43="pass","n/a","n/a"))) | X43: BACKTEST wc 2022
A44: wc22-e-esp-crc-20221123 | B44: T-1h | C44: 2048 | D44: 1741 | E44: 0 | F44: 8 | G44: 1 | H44: 1 | I44: 0.755207 | J44: 0.1158 | K44: 0.128993 | L44: 0.852692 | M44: 0.101425 | N44: 0.045883 | O44: 0 | P44: 0 | Q44: 0 | R44: pick | S44: Costa Rica | T44: polymarket | U44: 8.31 | V44: =(I44-O44)^2+(J44-P44)^2+(K44-Q44)^2 | W44: =IF(B44<>"KO","",IF(R44="pick",IF(VLOOKUP(A44,'Match Universe'!A:K,11,FALSE)=S44,"hit","miss"),IF(R44="pass","n/a","n/a"))) | X44: BACKTEST wc 2022
A45: wc22-e-esp-crc-20221123 | B45: KO | C45: 2048 | D45: 1741 | E45: 0 | F45: 8 | G45: 1 | H45: 1 | I45: 0.755207 | J45: 0.1158 | K45: 0.128993 | L45: 0.852692 | M45: 0.101425 | N45: 0.045883 | O45: 1 | P45: 0 | Q45: 0 | R45: pick | S45: Costa Rica | T45: polymarket | U45: 8.31 | V45: =(I45-O45)^2+(J45-P45)^2+(K45-Q45)^2 | W45: =IF(B45<>"KO","",IF(R45="pick",IF(VLOOKUP(A45,'Match Universe'!A:K,11,FALSE)=S45,"hit","miss"),IF(R45="pass","n/a","n/a"))) | X45: BACKTEST wc 2022
A46: wc22-f-bel-can-20221123 | B46: T-38 | C46: 2025 | D46: 1748 | E46: 0 | F46: 18 | G46: 1 | H46: 1 | I46: 0.720032 | J46: 0.1338 | K46: 0.146168 | L46: 0.615421 | M46: 0.235532 | N46: 0.149047 | O46: 0 | P46: 0 | Q46: 0 | R46: pass | V46: =(I46-O46)^2+(J46-P46)^2+(K46-Q46)^2 | W46: =IF(B46<>"KO","",IF(R46="pick",IF(VLOOKUP(A46,'Match Universe'!A:K,11,FALSE)=S46,"hit","miss"),IF(R46="pass","n/a","n/a"))) | X46: BACKTEST wc 2022
A47: wc22-f-bel-can-20221123 | B47: T-5 | C47: 2025 | D47: 1748 | E47: 0 | F47: 18 | G47: 1 | H47: 1 | I47: 0.720032 | J47: 0.1338 | K47: 0.146168 | L47: 0.615421 | M47: 0.235532 | N47: 0.149047 | O47: 0 | P47: 0 | Q47: 0 | R47: pass | V47: =(I47-O47)^2+(J47-P47)^2+(K47-Q47)^2 | W47: =IF(B47<>"KO","",IF(R47="pick",IF(VLOOKUP(A47,'Match Universe'!A:K,11,FALSE)=S47,"hit","miss"),IF(R47="pass","n/a","n/a"))) | X47: BACKTEST wc 2022
A48: wc22-f-bel-can-20221123 | B48: T-1h | C48: 2025 | D48: 1748 | E48: 0 | F48: 18 | G48: 1 | H48: 1 | I48: 0.720032 | J48: 0.1338 | K48: 0.146168 | L48: 0.615421 | M48: 0.235532 | N48: 0.149047 | O48: 0 | P48: 0 | Q48: 0 | R48: pass | V48: =(I48-O48)^2+(J48-P48)^2+(K48-Q48)^2 | W48: =IF(B48<>"KO","",IF(R48="pick",IF(VLOOKUP(A48,'Match Universe'!A:K,11,FALSE)=S48,"hit","miss"),IF(R48="pass","n/a","n/a"))) | X48: BACKTEST wc 2022
A49: wc22-f-bel-can-20221123 | B49: KO | C49: 2025 | D49: 1748 | E49: 0 | F49: 18 | G49: 1 | H49: 1 | I49: 0.720032 | J49: 0.1338 | K49: 0.146168 | L49: 0.615421 | M49: 0.235532 | N49: 0.149047 | O49: 1 | P49: 0 | Q49: 0 | R49: pass | V49: =(I49-O49)^2+(J49-P49)^2+(K49-Q49)^2 | W49: =IF(B49<>"KO","",IF(R49="pick",IF(VLOOKUP(A49,'Match Universe'!A:K,11,FALSE)=S49,"hit","miss"),IF(R49="pass","n/a","n/a"))) | X49: BACKTEST wc 2022
A50: wc22-g-sui-cmr-20221124 | B50: T-38 | C50: 1881 | D50: 1739 | E50: 0 | F50: 8 | G50: 1 | H50: 1 | I50: 0.544684 | J50: 0.2148 | K50: 0.240516 | L50: 0.526279 | M50: 0.279157 | N50: 0.194564 | O50: 0 | P50: 0 | Q50: 0 | R50: pass | V50: =(I50-O50)^2+(J50-P50)^2+(K50-Q50)^2 | W50: =IF(B50<>"KO","",IF(R50="pick",IF(VLOOKUP(A50,'Match Universe'!A:K,11,FALSE)=S50,"hit","miss"),IF(R50="pass","n/a","n/a"))) | X50: BACKTEST wc 2022
A51: wc22-g-sui-cmr-20221124 | B51: T-5 | C51: 1881 | D51: 1739 | E51: 0 | F51: 8 | G51: 1 | H51: 1 | I51: 0.544684 | J51: 0.2148 | K51: 0.240516 | L51: 0.526279 | M51: 0.279157 | N51: 0.194564 | O51: 0 | P51: 0 | Q51: 0 | R51: pass | V51: =(I51-O51)^2+(J51-P51)^2+(K51-Q51)^2 | W51: =IF(B51<>"KO","",IF(R51="pick",IF(VLOOKUP(A51,'Match Universe'!A:K,11,FALSE)=S51,"hit","miss"),IF(R51="pass","n/a","n/a"))) | X51: BACKTEST wc 2022
A52: wc22-g-sui-cmr-20221124 | B52: T-1h | C52: 1881 | D52: 1739 | E52: 0 | F52: 8 | G52: 1 | H52: 1 | I52: 0.544684 | J52: 0.2148 | K52: 0.240516 | L52: 0.526279 | M52: 0.279157 | N52: 0.194564 | O52: 0 | P52: 0 | Q52: 0 | R52: pass | V52: =(I52-O52)^2+(J52-P52)^2+(K52-Q52)^2 | W52: =IF(B52<>"KO","",IF(R52="pick",IF(VLOOKUP(A52,'Match Universe'!A:K,11,FALSE)=S52,"hit","miss"),IF(R52="pass","n/a","n/a"))) | X52: BACKTEST wc 2022
A53: wc22-g-sui-cmr-20221124 | B53: KO | C53: 1881 | D53: 1739 | E53: 0 | F53: 8 | G53: 1 | H53: 1 | I53: 0.544684 | J53: 0.2148 | K53: 0.240516 | L53: 0.526279 | M53: 0.279157 | N53: 0.194564 | O53: 1 | P53: 0 | Q53: 0 | R53: pass | V53: =(I53-O53)^2+(J53-P53)^2+(K53-Q53)^2 | W53: =IF(B53<>"KO","",IF(R53="pick",IF(VLOOKUP(A53,'Match Universe'!A:K,11,FALSE)=S53,"hit","miss"),IF(R53="pass","n/a","n/a"))) | X53: BACKTEST wc 2022
A54: wc22-h-uru-kor-20221124 | B54: T-38 | C54: 1909 | D54: 1786 | E54: 0 | F54: 18 | G54: 1 | H54: 1 | I54: 0.518422 | J54: 0.2262 | K54: 0.255378 | L54: 0.516971 | M54: 0.289817 | N54: 0.193211 | O54: 0 | P54: 0 | Q54: 0 | R54: pass | V54: =(I54-O54)^2+(J54-P54)^2+(K54-Q54)^2 | W54: =IF(B54<>"KO","",IF(R54="pick",IF(VLOOKUP(A54,'Match Universe'!A:K,11,FALSE)=S54,"hit","miss"),IF(R54="pass","n/a","n/a"))) | X54: BACKTEST wc 2022
A55: wc22-h-uru-kor-20221124 | B55: T-5 | C55: 1909 | D55: 1786 | E55: 0 | F55: 18 | G55: 1 | H55: 1 | I55: 0.518422 | J55: 0.2262 | K55: 0.255378 | L55: 0.516971 | M55: 0.289817 | N55: 0.193211 | O55: 0 | P55: 0 | Q55: 0 | R55: pass | V55: =(I55-O55)^2+(J55-P55)^2+(K55-Q55)^2 | W55: =IF(B55<>"KO","",IF(R55="pick",IF(VLOOKUP(A55,'Match Universe'!A:K,11,FALSE)=S55,"hit","miss"),IF(R55="pass","n/a","n/a"))) | X55: BACKTEST wc 2022
A56: wc22-h-uru-kor-20221124 | B56: T-1h | C56: 1909 | D56: 1786 | E56: 0 | F56: 18 | G56: 1 | H56: 1 | I56: 0.518422 | J56: 0.2262 | K56: 0.255378 | L56: 0.516971 | M56: 0.289817 | N56: 0.193211 | O56: 0 | P56: 0 | Q56: 0 | R56: pass | V56: =(I56-O56)^2+(J56-P56)^2+(K56-Q56)^2 | W56: =IF(B56<>"KO","",IF(R56="pick",IF(VLOOKUP(A56,'Match Universe'!A:K,11,FALSE)=S56,"hit","miss"),IF(R56="pass","n/a","n/a"))) | X56: BACKTEST wc 2022
A57: wc22-h-uru-kor-20221124 | B57: KO | C57: 1909 | D57: 1786 | E57: 0 | F57: 18 | G57: 1 | H57: 1 | I57: 0.518422 | J57: 0.2262 | K57: 0.255378 | L57: 0.516971 | M57: 0.289817 | N57: 0.193211 | O57: 0 | P57: 1 | Q57: 0 | R57: pass | V57: =(I57-O57)^2+(J57-P57)^2+(K57-Q57)^2 | W57: =IF(B57<>"KO","",IF(R57="pick",IF(VLOOKUP(A57,'Match Universe'!A:K,11,FALSE)=S57,"hit","miss"),IF(R57="pass","n/a","n/a"))) | X57: BACKTEST wc 2022
... A61: wc22-h-por-gha-20221124 | B61: KO | C61: 2040 | D61: 1685 | E61: 0 | F61: 8 | G61: 1 | H61: 1 | I61: 0.796764 | J61: 0.1 | K61: 0.103236 | L61: 0.667874 | M61: 0.217059 | N61: 0.115067 | O61: 1 | P61: 0 | Q61: 0 | R61: pass | V61: =(I61-O61)^2+(J61-P61)^2+(K61-Q61)^2 | W61: =IF(B61<>"KO","",IF(R61="pick",IF(VLOOKUP(A61,'Match Universe'!A:K,11,FALSE)=S61,"hit","miss"),IF(R61="pass","n/a","n/a"))) | X61: BACKTEST wc 2022
A62: wc22-g-bra-srb-20221124 | B62: T-38 | C62: 2169 | D62: 1804 | E62: 0 | F62: 8 | G62: 1 | H62: 1 | I62: 0.80191 | J62: 0.1 | K62: 0.09809 | L62: 0.640662 | M62: 0.224977 | N62: 0.134361 | O62: 0 | P62: 0 | Q62: 0 | R62: pick | S62: Brazil | T62: polymarket | U62: 16.12 | V62: =(I62-O62)^2+(J62-P62)^2+(K62-Q62)^2 | W62: =IF(B62<>"KO","",IF(R62="pick",IF(VLOOKUP(A62,'Match Universe'!A:K,11,FALSE)=S62,"hit","miss"),IF(R62="pass","n/a","n/a"))) | X62: BACKTEST wc 2022
A63: wc22-g-bra-srb-20221124 | B63: T-5 | C63: 2169 | D63: 1804 | E63: 0 | F63: 8 | G63: 1 | H63: 1 | I63: 0.80191 | J63: 0.1 | K63: 0.09809 | L63: 0.640662 | M63: 0.224977 | N63: 0.134361 | O63: 0 | P63: 0 | Q63: 0 | R63: pick | S63: Brazil | T63: polymarket | U63: 16.12 | V63: =(I63-O63)^2+(J63-P63)^2+(K63-Q63)^2 | W63: =IF(B63<>"KO","",IF(R63="pick",IF(VLOOKUP(A63,'Match Universe'!A:K,11,FALSE)=S63,"hit","miss"),IF(R63="pass","n/a","n/a"))) | X63: BACKTEST wc 2022
A64: wc22-g-bra-srb-20221124 | B64: T-1h | C64: 2169 | D64: 1804 | E64: 0 | F64: 8 | G64: 1 | H64: 1 | I64: 0.80191 | J64: 0.1 | K64: 0.09809 | L64: 0.640662 | M64: 0.224977 | N64: 0.134361 | O64: 0 | P64: 0 | Q64: 0 | R64: pick | S64: Brazil | T64: polymarket | U64: 16.12 | V64: =(I64-O64)^2+(J64-P64)^2+(K64-Q64)^2 | W64: =IF(B64<>"KO","",IF(R64="pick",IF(VLOOKUP(A64,'Match Universe'!A:K,11,FALSE)=S64,"hit","miss"),IF(R64="pass","n/a","n/a"))) | X64: BACKTEST wc 2022
A65: wc22-g-bra-srb-20221124 | B65: KO | C65: 2169 | D65: 1804 | E65: 0 | F65: 8 | G65: 1 | H65: 1 | I65: 0.80191 | J65: 0.1 | K65: 0.09809 | L65: 0.640662 | M65: 0.224977 | N65: 0.134361 | O65: 1 | P65: 0 | Q65: 0 | R65: pick | S65: Brazil | T65: polymarket | U65: 16.12 | V65: =(I65-O65)^2+(J65-P65)^2+(K65-Q65)^2 | W65: =IF(B65<>"KO","",IF(R65="pick",IF(VLOOKUP(A65,'Match Universe'!A:K,11,FALSE)=S65,"hit","miss"),IF(R65="pass","n/a","n/a"))) | X65: BACKTEST wc 2022
A66: wc22-b-wal-irn-20221125 | B66: T-38 | C66: 1789 | D66: 1818 | E66: 0 | F66: 18 | G66: 1 | H66: 1 | I66: 0.328829 | J66: 0.2826 | K66: 0.388571 | L66: 0.392819 | M66: 0.315543 | N66: 0.291638 | O66: 0 | P66: 0 | Q66: 0 | R66: pass | V66: =(I66-O66)^2+(J66-P66)^2+(K66-Q66)^2 | W66: =IF(B66<>"KO","",IF(R66="pick",IF(VLOOKUP(A66,'Match Universe'!A:K,11,FALSE)=S66,"hit","miss"),IF(R66="pass","n/a","n/a"))) | X66: BACKTEST wc 2022
...

Sheet Calibration
A1: bin_label | B1: bin_low | C1: bin_high | D1: n_predictions | E1: sum_observed | F1: predicted_rate | G1: observed_rate | H1: calibration_error
A2: 0–10% | B2: 0 | C2: 0.1 | D2: =SUMPRODUCT((Snapshots!I2:I100>=B2)*(Snapshots!I2:I100<C2)*(Snapshots!B2:B100="KO"))+SUMPRODUCT((Snapshots!J2:J100>=B2)*(Snapshots!J2:J100<C2)*(Snapshots!B2:B100="KO"))+SUMPRODUCT((Snapshots!K2:K100>=B2)*(Snapshots!K2:K100<C2)*(Snapshots!B2:B100="KO")) | E2: =SUMPRODUCT((Snapshots!I2:I100>=B2)*(Snapshots!I2:I100<C2)*(Snapshots!B2:B100="KO")*Snapshots!O2:O100)+SUMPRODUCT((Snapshots!J2:J100>=B2)*(Snapshots!J2:J100<C2)*(Snapshots!B2:B100="KO")*Snapshots!P2:P100)+SUMPRODUCT((Snapshots!K2:K100>=B2)*(Snapshots!K2:K100<C2)*(Snapshots!B2:B100="KO")*Snapshots!Q2:Q100) | F2: =(B2+C2)/2 | G2: =IF(D2=0,"",E2/D2) | H2: =IF(D2=0,"",F2-G2)
A3: 10–20% | B3: 0.1 | C3: 0.2 | D3: =SUMPRODUCT((Snapshots!I2:I100>=B3)*(Snapshots!I2:I100<C3)*(Snapshots!B2:B100="KO"))+SUMPRODUCT((Snapshots!J2:J100>=B3)*(Snapshots!J2:J100<C3)*(Snapshots!B2:B100="KO"))+SUMPRODUCT((Snapshots!K2:K100>=B3)*(Snapshots!K2:K100<C3)*(Snapshots!B2:B100="KO")) | E3: =SUMPRODUCT((Snapshots!I2:I100>=B3)*(Snapshots!I2:I100<C3)*(Snapshots!B2:B100="KO")*Snapshots!O2:O100)+SUMPRODUCT((Snapshots!J2:J100>=B3)*(Snapshots!J2:J100<C3)*(Snapshots!B2:B100="KO")*Snapshots!P2:P100)+SUMPRODUCT((Snapshots!K2:K100>=B3)*(Snapshots!K2:K100<C3)*(Snapshots!B2:B100="KO")*Snapshots!Q2:Q100) | F3: =(B3+C3)/2 | G3: =IF(D3=0,"",E3/D3) | H3: =IF(D3=0,"",F3-G3)
A4: 20–30% | B4: 0.2 | C4: 0.3 | D4: =SUMPRODUCT((Snapshots!I2:I100>=B4)*(Snapshots!I2:I100<C4)*(Snapshots!B2:B100="KO"))+SUMPRODUCT((Snapshots!J2:J100>=B4)*(Snapshots!J2:J100<C4)*(Snapshots!B2:B100="KO"))+SUMPRODUCT((Snapshots!K2:K100>=B4)*(Snapshots!K2:K100<C4)*(Snapshots!B2:B100="KO")) | E4: =SUMPRODUCT((Snapshots!I2:I100>=B4)*(Snapshots!I2:I100<C4)*(Snapshots!B2:B100="KO")*Snapshots!O2:O100)+SUMPRODUCT((Snapshots!J2:J100>=B4)*(Snapshots!J2:J100<C4)*(Snapshots!B2:B100="KO")*Snapshots!P2:P100)+SUMPRODUCT((Snapshots!K2:K100>=B4)*(Snapshots!K2:K100<C4)*(Snapshots!B2:B100="KO")*Snapshots!Q2:Q100) | F4: =(B4+C4)/2 | G4: =IF(D4=0,"",E4/D4) | H4: =IF(D4=0,"",F4-G4)
A5: 30–40% | B5: 0.3 | C5: 0.4 | D5: =SUMPRODUCT((Snapshots!I2:I100>=B5)*(Snapshots!I2:I100<C5)*(Snapshots!B2:B100="KO"))+SUMPRODUCT((Snapshots!J2:J100>=B5)*(Snapshots!J2:J100<C5)*(Snapshots!B2:B100="KO"))+SUMPRODUCT((Snapshots!K2:K100>=B5)*(Snapshots!K2:K100<C5)*(Snapshots!B2:B100="KO")) | E5: =SUMPRODUCT((Snapshots!I2:I100>=B5)*(Snapshots!I2:I100<C5)*(Snapshots!B2:B100="KO")*Snapshots!O2:O100)+SUMPRODUCT((Snapshots!J2:J100>=B5)*(Snapshots!J2:J100<C5)*(Snapshots!B2:B100="KO")*Snapshots!P2:P100)+SUMPRODUCT((Snapshots!K2:K100>=B5)*(Snapshots!K2:K100<C5)*(Snapshots!B2:B100="KO")*Snapshots!Q2:Q100) | F5: =(B5+C5)/2 | G5: =IF(D5=0,"",E5/D5) | H5: =IF(D5=0,"",F5-G5)
A6: 40–50% | B6: 0.4 | C6: 0.5 | D6: =SUMPRODUCT((Snapshots!I2:I100>=B6)*(Snapshots!I2:I100<C6)*(Snapshots!B2:B100="KO"))+SUMPRODUCT((Snapshots!J2:J100>=B6)*(Snapshots!J2:J100<C6)*(Snapshots!B2:B100="KO"))+SUMPRODUCT((Snapshots!K2:K100>=B6)*(Snapshots!K2:K100<C6)*(Snapshots!B2:B100="KO")) | E6: =SUMPRODUCT((Snapshots!I2:I100>=B6)*(Snapshots!I2:I100<C6)*(Snapshots!B2:B100="KO")*Snapshots!O2:O100)+SUMPRODUCT((Snapshots!J2:J100>=B6)*(Snapshots!J2:J100<C6)*(Snapshots!B2:B100="KO")*Snapshots!P2:P100)+SUMPRODUCT((Snapshots!K2:K100>=B6)*(Snapshots!K2:K100<C6)*(Snapshots!B2:B100="KO")*Snapshots!Q2:Q100) | F6: =(B6+C6)/2 | G6: =IF(D6=0,"",E6/D6) | H6: =IF(D6=0,"",F6-G6)
A7: 50–60% | B7: 0.5 | C7: 0.6 | D7: =SUMPRODUCT((Snapshots!I2:I100>=B7)*(Snapshots!I2:I100<C7)*(Snapshots!B2:B100="KO"))+SUMPRODUCT((Snapshots!J2:J100>=B7)*(Snapshots!J2:J100<C7)*(Snapshots!B2:B100="KO"))+SUMPRODUCT((Snapshots!K2:K100>=B7)*(Snapshots!K2:K100<C7)*(Snapshots!B2:B100="KO")) | E7: =SUMPRODUCT((Snapshots!I2:I100>=B7)*(Snapshots!I2:I100<C7)*(Snapshots!B2:B100="KO")*Snapshots!O2:O100)+SUMPRODUCT((Snapshots!J2:J100>=B7)*(Snapshots!J2:J100<C7)*(Snapshots!B2:B100="KO")*Snapshots!P2:P100)+SUMPRODUCT((Snapshots!K2:K100>=B7)*(Snapshots!K2:K100<C7)*(Snapshots!B2:B100="KO")*Snapshots!Q2:Q100) | F7: =(B7+C7)/2 | G7: =IF(D7=0,"",E7/D7) | H7: =IF(D7=0,"",F7-G7)
A8: 60–70% | B8: 0.6 | C8: 0.7 | D8: =SUMPRODUCT((Snapshots!I2:I100>=B8)*(Snapshots!I2:I100<C8)*(Snapshots!B2:B100="KO"))+SUMPRODUCT((Snapshots!J2:J100>=B8)*(Snapshots!J2:J100<C8)*(Snapshots!B2:B100="KO"))+SUMPRODUCT((Snapshots!K2:K100>=B8)*(Snapshots!K2:K100<C8)*(Snapshots!B2:B100="KO")) | E8: =SUMPRODUCT((Snapshots!I2:I100>=B8)*(Snapshots!I2:I100<C8)*(Snapshots!B2:B100="KO")*Snapshots!O2:O100)+SUMPRODUCT((Snapshots!J2:J100>=B8)*(Snapshots!J2:J100<C8)*(Snapshots!B2:B100="KO")*Snapshots!P2:P100)+SUMPRODUCT((Snapshots!K2:K100>=B8)*(Snapshots!K2:K100<C8)*(Snapshots!B2:B100="KO")*Snapshots!Q2:Q100) | F8: =(B8+C8)/2 | G8: =IF(D8=0,"",E8/D8) | H8: =IF(D8=0,"",F8-G8)
A9: 70–80% | B9: 0.7 | C9: 0.8 | D9: =SUMPRODUCT((Snapshots!I2:I100>=B9)*(Snapshots!I2:I100<C9)*(Snapshots!B2:B100="KO"))+SUMPRODUCT((Snapshots!J2:J100>=B9)*(Snapshots!J2:J100<C9)*(Snapshots!B2:B100="KO"))+SUMPRODUCT((Snapshots!K2:K100>=B9)*(Snapshots!K2:K100<C9)*(Snapshots!B2:B100="KO")) | E9: =SUMPRODUCT((Snapshots!I2:I100>=B9)*(Snapshots!I2:I100<C9)*(Snapshots!B2:B100="KO")*Snapshots!O2:O100)+SUMPRODUCT((Snapshots!J2:J100>=B9)*(Snapshots!J2:J100<C9)*(Snapshots!B2:B100="KO")*Snapshots!P2:P100)+SUMPRODUCT((Snapshots!K2:K100>=B9)*(Snapshots!K2:K100<C9)*(Snapshots!B2:B100="KO")*Snapshots!Q2:Q100) | F9: =(B9+C9)/2 | G9: =IF(D9=0,"",E9/D9) | H9: =IF(D9=0,"",F9-G9)
A10: 80–90% | B10: 0.8 | C10: 0.9 | D10: =SUMPRODUCT((Snapshots!I2:I100>=B10)*(Snapshots!I2:I100<C10)*(Snapshots!B2:B100="KO"))+SUMPRODUCT((Snapshots!J2:J100>=B10)*(Snapshots!J2:J100<C10)*(Snapshots!B2:B100="KO"))+SUMPRODUCT((Snapshots!K2:K100>=B10)*(Snapshots!K2:K100<C10)*(Snapshots!B2:B100="KO")) | E10: =SUMPRODUCT((Snapshots!I2:I100>=B10)*(Snapshots!I2:I100<C10)*(Snapshots!B2:B100="KO")*Snapshots!O2:O100)+SUMPRODUCT((Snapshots!J2:J100>=B10)*(Snapshots!J2:J100<C10)*(Snapshots!B2:B100="KO")*Snapshots!P2:P100)+SUMPRODUCT((Snapshots!K2:K100>=B10)*(Snapshots!K2:K100<C10)*(Snapshots!B2:B100="KO")*Snapshots!Q2:Q100) | F10: =(B10+C10)/2 | G10: =IF(D10=0,"",E10/D10) | H10: =IF(D10=0,"",F10-G10)
A11: 90–100% | B11: 0.9 | C11: 1 | D11: =SUMPRODUCT((Snapshots!I2:I100>=B11)*(Snapshots!I2:I100<C11)*(Snapshots!B2:B100="KO"))+SUMPRODUCT((Snapshots!J2:J100>=B11)*(Snapshots!J2:J100<C11)*(Snapshots!B2:B100="KO"))+SUMPRODUCT((Snapshots!K2:K100>=B11)*(Snapshots!K2:K100<C11)*(Snapshots!B2:B100="KO")) | E11: =SUMPRODUCT((Snapshots!I2:I100>=B11)*(Snapshots!I2:I100<C11)*(Snapshots!B2:B100="KO")*Snapshots!O2:O100)+SUMPRODUCT((Snapshots!J2:J100>=B11)*(Snapshots!J2:J100<C11)*(Snapshots!B2:B100="KO")*Snapshots!P2:P100)+SUMPRODUCT((Snapshots!K2:K100>=B11)*(Snapshots!K2:K100<C11)*(Snapshots!B2:B100="KO")*Snapshots!Q2:Q100) | F11: =(B11+C11)/2 | G11: =IF(D11=0,"",E11/D11) | H11: =IF(D11=0,"",F11-G11)
A13: Reliability bins: each (probability, outcome) pair from a KO snapshot contributes one data point. Each snapshot supplies three pairs (team_a, draw, team_b). A perfectly calibrated model has observed_rate ≈ predicted_rate in every bin (calibration_error ≈ 0).

Sheet Metrics
A1: DESK BACKTEST — METRICS SUMMARY
A3: Headline numbers (KO snapshots only)
A4: Total KO snapshots in scope | B4: =SUMPRODUCT((Snapshots!B2:B100="KO")*1)
A5: Mean Brier score (model) | B5: =AVERAGEIFS(Snapshots!V2:V100,Snapshots!B2:B100,"KO")
A7: Verdict mix (KO snapshots only)
A8: Picks issued | B8: =COUNTIFS(Snapshots!R2:R100,"pick",Snapshots!B2:B100,"KO")
A9: Passes issued | B9: =COUNTIFS(Snapshots!R2:R100,"pass",Snapshots!B2:B100,"KO")
A10: Avoids issued | B10: =COUNTIFS(Snapshots!R2:R100,"avoid",Snapshots!B2:B100,"KO")
A12: Edge analysis (Pick verdicts only)
A13: Mean edge_pp on Picks | B13: =AVERAGEIFS(Snapshots!U2:U100,Snapshots!R2:R100,"pick",Snapshots!B2:B100,"KO")
A14: Largest single edge_pp | B14: =IFERROR(aggregate(14,6,Snapshots!U2:U100/((Snapshots!R2:R100="pick")*(Snapshots!B2:B100="KO")),1),"")
A16: Pick resolution (manual review required)
A17: Picks marked 'manual' for review | B17: =COUNTIFS(Snapshots!W2:W100,"manual")
A18: Picks resolved as hits | B18: =COUNTIFS(Snapshots!W2:W100,"hit")
A19: Picks resolved as misses | B19: =COUNTIFS(Snapshots!W2:W100,"miss")
A20: Pick hit rate (sanity check, not headline) | B20: =IF(COUNTIFS(Snapshots!W2:W100,"hit")+COUNTIFS(Snapshots!W2:W100,"miss")=0,"",COUNTIFS(Snapshots!W2:W100,"hit")/(COUNTIFS(Snapshots!W2:W100,"hit")+COUNTIFS(Snapshots!W2:W100,"miss")))
A22: Calibration headline
A23: Mean absolute calibration error | B23: =IFERROR(AVERAGEIFS(Calibration!H2:H11,Calibration!D2:D11,">0"),"")
A25: Closing-market baseline (to compute when populated)
A26: Mean Brier score (market) | C26: Compute as AVERAGEIFS over (market_p_a-actual_a)^2+... once market columns are filled. The Desk wins if model.brier < market.brier.
A28: Headline read order: 1) calibration error (lower = more honest), 2) Brier vs market baseline (lower = better), 3) edge magnitude on Picks (sanity), 4) Pick hit rate (sanity only — never the headline number).

Sheet Open Questions
A1: # | B1: Question | C1: Why it matters | D1: Status
A2: 1 | B2: Source of historical Elo at each time window | C2: eloratings.net is JS-rendered (rejected for live use). Wikipedia data module has historical snapshots — confirm coverage at T-38d back to 2022. → DECISION: Wikipedia data module — confirmed source for historical Elo at all time windows. | D2: LOCKED
A3: 2 | B3: Closing-market baseline source | C3: Kalshi/Polymarket weren't liquid for WC 2022. Use Pinnacle / Betfair Exchange archives as the baseline. Pinnacle is the gold standard. → DECISION: Pinnacle archives + Betfair Exchange where Pinnacle missing — gold-standard closing-line baseline. | D3: LOCKED
A4: 3 | B4: Injury / availability reconstruction | C4: Hardest piece. Either (a) skip late-binding adjustments in the backtest (T-1h = same as T-3d), (b) hand-code injuries for 5-10 marquee matches, (c) scrape archive.org for ESPN/BBC team news pages by date. → DECISION: Option C: scrape archive.org snapshots of ESPN/BBC team-news pages by date. Hand-code marquee matches as fallback. | D4: LOCKED
A5: 4 | B5: Verdict resolution rules at KO | C5: Pick = correct if verdict.side actually won in 90 min. Pass / Avoid = unresolved by definition (no action). Confirm. → DECISION: Confirmed: Pick = correct iff verdict.side actually won in 90 min. Pass / Avoid = unresolved (no action taken). | D5: LOCKED
A6: 5 | B6: Pick threshold (edge_pp) for the backtest | C6: v1 design says ~1pp = Pass, but the live Pick threshold isn't yet locked. The backtest will be sensitive to this — run sweeps at 2/3/5pp. → DECISION: Pick threshold = 3pp default; sensitivity sweep at 2pp and 5pp. Below 2pp is noise; 3pp filters marginal edges. | D6: LOCKED
A7: 6 | B7: Calibration binning strategy | C7: Current scaffold uses 10% bins. Consider isotonic-regression smoothing for the diagram. With ~150 matches × 3 outcomes = ~450 data points, 10 bins is appropriate. → DECISION: 10% bins (0–10%, 10–20%, …, 90–100%). With 441 data points, ~44 per bin. Isotonic smoothing is v2. | D7: LOCKED
A8: 7 | B8: Penalty-shootout handling | C8: Argentina-France 2022 went to pens. The 1X2 model is 90-min only. Confirm this convention is honest — and that we're not silently scoring penalty wins as 90-min wins. → DECISION: 90-minute outcomes only. Penalty-shootout winners do NOT count as 90-min winners. Already-decided. | D8: LOCKED
A9: 8 | B9: Tournament-specific Elo rebase | C9: International Elo doesn't carry over cleanly between tournaments. Decide whether to use pre-tournament snapshots only or rolling Elo. → DECISION: Pre-tournament Elo snapshot only. Freeze each team's Elo the day before the tournament; don't update during. Rolling Elo is v2. | D9: LOCKED
A10: 9 | B10: Backtest deliverable format | C10: Output target: a /track-record page with reliability diagram + selected commentary. Decide whether to publish raw match-by-match table or a curated narrative + summary stats. → DECISION: HTML dashboard at desk_backtest_dashboard.html. Embeds reliability diagram + KPIs + match table. Foundation for /track-record page. | D10: LOCKED
A12: All open questions resolved 2026-05-08. Workbook is ready to populate with real data once Wikipedia Elo / Pinnacle archive / archive.org news pipeline is in place.
